<?xml version="1.0"?>
<robot xmlns:xacro="http://www.ros.org/wiki/xacro" name="mpo_500">

  <xacro:macro name="mpo_500_trailer_base" params="name parent *origin">
    <joint name="${name}_joint" type="revolute">
      <xacro:insert_block name="origin" />
      <axis xyz="0 0 -1" />
      <limit effort="1000.0" lower="-1.57" upper="1.57" velocity="0.5"/>
      
      <parent link="${parent}" />
      <child link="${name}" />
   </joint>
    <link name="${name}">
      <inertial>
        <mass value="64"/>
        <origin xyz="0 0.0 0.0" />
         <inertia ixx="2.8" ixy="0.0" ixz="0.0"
                 iyy="2.8" iyz="0.0" 
                 izz="2.8" />
      </inertial>
      <visual>
        <origin xyz="-0.5 0. 0.25" rpy="-1.571 0 1.571" />
        <geometry>
          <box size="1 0.25 1.5"/>
        </geometry>
      </visual>
      <collision>
        <origin xyz="-0.5 0. 0.25" rpy="-1.571 0 1.571" />
        <geometry>
          <box size="1 0.25 1.5"/> 
        </geometry>
      </collision>
    </link>

  </xacro:macro>
  
</robot>
