<?xml version="1.0"?>
<robot xmlns:xacro="http://www.ros.org/wiki/xacro" name="mpo_500">

  <!--xacro:include filename="$(find PeTRA)/neo_simulation/robots/mpo_500/xacros/mpo_500_trailer_parameter.xacro"/-->
  <xacro:include filename="$(find neo_simulation)/robots/mpo_500/xacros/mpo_500_trailer_parameter.xacro" />

  <xacro:macro name="mpo_500_trailer_base" params="name parent *origin">
    <joint name="${name}_joint" type="revolute">
      <xacro:insert_block name="origin" />
      <axis xyz="0 0 -1" />
      <limit effort="1000.0" lower="-1.57" upper="1.57" velocity="0.5"/>
      
      <parent link="${parent}" />
      <child link="${name}" />
   </joint>
    <link name="${name}">
      <inertial>
        <mass value="64"/>
        <origin xyz="0 0.0 0.0" />
         <inertia ixx="2.8" ixy="0.0" ixz="0.0"
                 iyy="2.8" iyz="0.0" 
                 izz="2.8" />
        
      </inertial>
      <visual>
        <origin xyz="${x_origin_chassis_trailer} ${y_origin_chassis_trailer} ${z_origin_chassis_trailer}" rpy="-1.571 0 1.571" />
        <geometry>
          <box size="${y_length_chassis_trailer} ${z_length_chassis_trailer} ${x_length_chassis_trailer}"/>
        </geometry>
      </visual>
      <collision>
        <origin xyz="${x_origin_chassis_trailer} ${y_origin_chassis_trailer} ${z_origin_chassis_trailer}" rpy="-1.571 0 1.571" />
        <geometry>
          <box size="${y_length_chassis_trailer} ${z_length_chassis_trailer} ${x_length_chassis_trailer}"/> 
        </geometry>
      </collision>
    </link>

  </xacro:macro>
  
</robot>
